> plugin setup...
< plugin setup.
Fetching genesis transactions from: http://test.bcovrin.vonx.io/genesis
Create profile manager: in_memory
Ledger instance not provided
No ledger configured
Exception during startup:
Traceback (most recent call last):
  File "/usr/local/lib/python3.9/site-packages/aries_cloudagent/commands/start.py", line 72, in init
    await startup
  File "/usr/local/lib/python3.9/site-packages/aries_cloudagent/commands/start.py", line 28, in start_app
    await conductor.setup()
  File "/usr/local/lib/python3.9/site-packages/aries_cloudagent/core/conductor.py", line 202, in setup
    self.dispatcher = Dispatcher(self.root_profile)
  File "/usr/local/lib/python3.9/site-packages/aries_cloudagent/core/dispatcher.py", line 57, in __init__
    self.logger: logging.Logger = get_logger_inst(
  File "/usr/local/lib/python3.9/site-packages/aries_cloudagent/config/logging.py", line 531, in get_logger_inst
    did_ident = get_did_ident(profile)
  File "/usr/local/lib/python3.9/site-packages/aries_cloudagent/config/logging.py", line 560, in get_did_ident
    did_ident = loop.run_until_complete(_fetch_did())
  File "/usr/local/lib/python3.9/site-packages/nest_asyncio.py", line 99, in run_until_complete
    return f.result()
  File "/usr/local/lib/python3.9/asyncio/futures.py", line 201, in result
    raise self._exception
  File "/usr/local/lib/python3.9/asyncio/tasks.py", line 256, in __step
    result = coro.send(None)
  File "/usr/local/lib/python3.9/site-packages/aries_cloudagent/config/logging.py", line 554, in _fetch_did
    req_did_info: DIDInfo = (await wallet.get_local_dids())[0]
IndexError: list index out of range
